<?xml version="1.0" encoding="UTF-8"?>
<testng-results skipped="0" failed="5" total="5" passed="0">
  <reporter-output>
  </reporter-output>
  <suite name="Default suite" duration-ms="12001" started-at="2013-10-28T17:20:10Z" finished-at="2013-10-28T17:20:22Z">
    <groups>
      <group name="corsAPI_ao">
        <method signature="Cors_Positive_AllowedOrigin_Test.negativeDelete_Test()[pri:0, instance:test.java.Cors_Positive_AllowedOrigin_Test@5bbeffcd]" name="negativeDelete_Test" class="test.java.Cors_Positive_AllowedOrigin_Test"/>
        <method signature="Cors_Positive_AllowedOrigin_Test.negativeGet_Test()[pri:0, instance:test.java.Cors_Positive_AllowedOrigin_Test@5bbeffcd]" name="negativeGet_Test" class="test.java.Cors_Positive_AllowedOrigin_Test"/>
        <method signature="Cors_Positive_AllowedOrigin_Test.negativeHead_Test()[pri:0, instance:test.java.Cors_Positive_AllowedOrigin_Test@5bbeffcd]" name="negativeHead_Test" class="test.java.Cors_Positive_AllowedOrigin_Test"/>
        <method signature="Cors_Positive_AllowedOrigin_Test.negativePost_Test()[pri:0, instance:test.java.Cors_Positive_AllowedOrigin_Test@5bbeffcd]" name="negativePost_Test" class="test.java.Cors_Positive_AllowedOrigin_Test"/>
        <method signature="Cors_Positive_AllowedOrigin_Test.negativePut_Test()[pri:0, instance:test.java.Cors_Positive_AllowedOrigin_Test@5bbeffcd]" name="negativePut_Test" class="test.java.Cors_Positive_AllowedOrigin_Test"/>
      </group> <!-- corsAPI_ao -->
    </groups>
    <test name="Default test" duration-ms="12001" started-at="2013-10-28T17:20:10Z" finished-at="2013-10-28T17:20:22Z">
      <class name="test.java.Cors_Positive_AllowedOrigin_Test">
        <test-method status="PASS" signature="initLogger()[pri:0, instance:test.java.Cors_Positive_AllowedOrigin_Test@5bbeffcd]" name="initLogger" is-config="true" duration-ms="21" started-at="2013-10-28T19:20:10Z" finished-at="2013-10-28T19:20:10Z">
          <reporter-output>
          </reporter-output>
        </test-method> <!-- initLogger -->
        <test-method status="PASS" signature="createDriver()[pri:0, instance:test.java.Cors_Positive_AllowedOrigin_Test@5bbeffcd]" name="createDriver" is-config="true" duration-ms="3541" started-at="2013-10-28T19:20:10Z" finished-at="2013-10-28T19:20:14Z">
          <reporter-output>
          </reporter-output>
        </test-method> <!-- createDriver -->
        <test-method status="PASS" signature="init()[pri:0, instance:test.java.Cors_Positive_AllowedOrigin_Test@5bbeffcd]" name="init" is-config="true" duration-ms="254" started-at="2013-10-28T19:20:14Z" depends-on-methods="test.java.TestInitialize.createDriver" finished-at="2013-10-28T19:20:14Z">
          <reporter-output>
          </reporter-output>
        </test-method> <!-- init -->
        <test-method status="FAIL" signature="negativeDelete_Test()[pri:0, instance:test.java.Cors_Positive_AllowedOrigin_Test@5bbeffcd]" name="negativeDelete_Test" duration-ms="2119" started-at="2013-10-28T19:20:14Z" finished-at="2013-10-28T19:20:16Z">
          <exception class="java.lang.AssertionError">
            <message>
              <![CDATA[expected [200] but found [Failure]]]>
            </message>
            <full-stacktrace>
              <![CDATA[java.lang.AssertionError: expected [200] but found [Failure]
	at org.testng.Assert.fail(Assert.java:94)
	at org.testng.Assert.failNotEquals(Assert.java:494)
	at org.testng.Assert.assertEquals(Assert.java:123)
	at org.testng.Assert.assertEquals(Assert.java:176)
	at org.testng.Assert.assertEquals(Assert.java:186)
	at test.java.Cors_Positive_AllowedOrigin_Test.negativeDelete_Test(Cors_Positive_AllowedOrigin_Test.java:60)
	at sun.reflect.NativeMethodAccessorImpl.invoke0(Native Method)
	at sun.reflect.NativeMethodAccessorImpl.invoke(Unknown Source)
	at sun.reflect.DelegatingMethodAccessorImpl.invoke(Unknown Source)
	at java.lang.reflect.Method.invoke(Unknown Source)
	at org.testng.internal.MethodInvocationHelper.invokeMethod(MethodInvocationHelper.java:84)
	at org.testng.internal.Invoker.invokeMethod(Invoker.java:714)
	at org.testng.internal.Invoker.invokeTestMethod(Invoker.java:901)
	at org.testng.internal.Invoker.invokeTestMethods(Invoker.java:1231)
	at org.testng.internal.TestMethodWorker.invokeTestMethods(TestMethodWorker.java:127)
	at org.testng.internal.TestMethodWorker.run(TestMethodWorker.java:111)
	at org.testng.TestRunner.privateRun(TestRunner.java:767)
	at org.testng.TestRunner.run(TestRunner.java:617)
	at org.testng.SuiteRunner.runTest(SuiteRunner.java:334)
	at org.testng.SuiteRunner.runSequentially(SuiteRunner.java:329)
	at org.testng.SuiteRunner.privateRun(SuiteRunner.java:291)
	at org.testng.SuiteRunner.run(SuiteRunner.java:240)
	at org.testng.SuiteRunnerWorker.runSuite(SuiteRunnerWorker.java:52)
	at org.testng.SuiteRunnerWorker.run(SuiteRunnerWorker.java:86)
	at org.testng.TestNG.runSuitesSequentially(TestNG.java:1224)
	at org.testng.TestNG.runSuitesLocally(TestNG.java:1149)
	at org.testng.TestNG.run(TestNG.java:1057)
	at org.testng.remote.RemoteTestNG.run(RemoteTestNG.java:111)
	at org.testng.remote.RemoteTestNG.initAndRun(RemoteTestNG.java:204)
	at org.testng.remote.RemoteTestNG.main(RemoteTestNG.java:175)
]]>
            </full-stacktrace>
          </exception> <!-- java.lang.AssertionError -->
          <reporter-output>
          </reporter-output>
        </test-method> <!-- negativeDelete_Test -->
        <test-method status="FAIL" signature="negativeGet_Test()[pri:0, instance:test.java.Cors_Positive_AllowedOrigin_Test@5bbeffcd]" name="negativeGet_Test" duration-ms="1446" started-at="2013-10-28T19:20:16Z" finished-at="2013-10-28T19:20:18Z">
          <exception class="java.lang.AssertionError">
            <message>
              <![CDATA[expected [200] but found [Failure]]]>
            </message>
            <full-stacktrace>
              <![CDATA[java.lang.AssertionError: expected [200] but found [Failure]
	at org.testng.Assert.fail(Assert.java:94)
	at org.testng.Assert.failNotEquals(Assert.java:494)
	at org.testng.Assert.assertEquals(Assert.java:123)
	at org.testng.Assert.assertEquals(Assert.java:176)
	at org.testng.Assert.assertEquals(Assert.java:186)
	at test.java.Cors_Positive_AllowedOrigin_Test.negativeGet_Test(Cors_Positive_AllowedOrigin_Test.java:42)
	at sun.reflect.NativeMethodAccessorImpl.invoke0(Native Method)
	at sun.reflect.NativeMethodAccessorImpl.invoke(Unknown Source)
	at sun.reflect.DelegatingMethodAccessorImpl.invoke(Unknown Source)
	at java.lang.reflect.Method.invoke(Unknown Source)
	at org.testng.internal.MethodInvocationHelper.invokeMethod(MethodInvocationHelper.java:84)
	at org.testng.internal.Invoker.invokeMethod(Invoker.java:714)
	at org.testng.internal.Invoker.invokeTestMethod(Invoker.java:901)
	at org.testng.internal.Invoker.invokeTestMethods(Invoker.java:1231)
	at org.testng.internal.TestMethodWorker.invokeTestMethods(TestMethodWorker.java:127)
	at org.testng.internal.TestMethodWorker.run(TestMethodWorker.java:111)
	at org.testng.TestRunner.privateRun(TestRunner.java:767)
	at org.testng.TestRunner.run(TestRunner.java:617)
	at org.testng.SuiteRunner.runTest(SuiteRunner.java:334)
	at org.testng.SuiteRunner.runSequentially(SuiteRunner.java:329)
	at org.testng.SuiteRunner.privateRun(SuiteRunner.java:291)
	at org.testng.SuiteRunner.run(SuiteRunner.java:240)
	at org.testng.SuiteRunnerWorker.runSuite(SuiteRunnerWorker.java:52)
	at org.testng.SuiteRunnerWorker.run(SuiteRunnerWorker.java:86)
	at org.testng.TestNG.runSuitesSequentially(TestNG.java:1224)
	at org.testng.TestNG.runSuitesLocally(TestNG.java:1149)
	at org.testng.TestNG.run(TestNG.java:1057)
	at org.testng.remote.RemoteTestNG.run(RemoteTestNG.java:111)
	at org.testng.remote.RemoteTestNG.initAndRun(RemoteTestNG.java:204)
	at org.testng.remote.RemoteTestNG.main(RemoteTestNG.java:175)
]]>
            </full-stacktrace>
          </exception> <!-- java.lang.AssertionError -->
          <reporter-output>
          </reporter-output>
        </test-method> <!-- negativeGet_Test -->
        <test-method status="FAIL" signature="negativeHead_Test()[pri:0, instance:test.java.Cors_Positive_AllowedOrigin_Test@5bbeffcd]" name="negativeHead_Test" duration-ms="1366" started-at="2013-10-28T19:20:18Z" finished-at="2013-10-28T19:20:19Z">
          <exception class="java.lang.AssertionError">
            <message>
              <![CDATA[expected [200] but found [Failure]]]>
            </message>
            <full-stacktrace>
              <![CDATA[java.lang.AssertionError: expected [200] but found [Failure]
	at org.testng.Assert.fail(Assert.java:94)
	at org.testng.Assert.failNotEquals(Assert.java:494)
	at org.testng.Assert.assertEquals(Assert.java:123)
	at org.testng.Assert.assertEquals(Assert.java:176)
	at org.testng.Assert.assertEquals(Assert.java:186)
	at test.java.Cors_Positive_AllowedOrigin_Test.negativeHead_Test(Cors_Positive_AllowedOrigin_Test.java:66)
	at sun.reflect.NativeMethodAccessorImpl.invoke0(Native Method)
	at sun.reflect.NativeMethodAccessorImpl.invoke(Unknown Source)
	at sun.reflect.DelegatingMethodAccessorImpl.invoke(Unknown Source)
	at java.lang.reflect.Method.invoke(Unknown Source)
	at org.testng.internal.MethodInvocationHelper.invokeMethod(MethodInvocationHelper.java:84)
	at org.testng.internal.Invoker.invokeMethod(Invoker.java:714)
	at org.testng.internal.Invoker.invokeTestMethod(Invoker.java:901)
	at org.testng.internal.Invoker.invokeTestMethods(Invoker.java:1231)
	at org.testng.internal.TestMethodWorker.invokeTestMethods(TestMethodWorker.java:127)
	at org.testng.internal.TestMethodWorker.run(TestMethodWorker.java:111)
	at org.testng.TestRunner.privateRun(TestRunner.java:767)
	at org.testng.TestRunner.run(TestRunner.java:617)
	at org.testng.SuiteRunner.runTest(SuiteRunner.java:334)
	at org.testng.SuiteRunner.runSequentially(SuiteRunner.java:329)
	at org.testng.SuiteRunner.privateRun(SuiteRunner.java:291)
	at org.testng.SuiteRunner.run(SuiteRunner.java:240)
	at org.testng.SuiteRunnerWorker.runSuite(SuiteRunnerWorker.java:52)
	at org.testng.SuiteRunnerWorker.run(SuiteRunnerWorker.java:86)
	at org.testng.TestNG.runSuitesSequentially(TestNG.java:1224)
	at org.testng.TestNG.runSuitesLocally(TestNG.java:1149)
	at org.testng.TestNG.run(TestNG.java:1057)
	at org.testng.remote.RemoteTestNG.run(RemoteTestNG.java:111)
	at org.testng.remote.RemoteTestNG.initAndRun(RemoteTestNG.java:204)
	at org.testng.remote.RemoteTestNG.main(RemoteTestNG.java:175)
]]>
            </full-stacktrace>
          </exception> <!-- java.lang.AssertionError -->
          <reporter-output>
          </reporter-output>
        </test-method> <!-- negativeHead_Test -->
        <test-method status="FAIL" signature="negativePost_Test()[pri:0, instance:test.java.Cors_Positive_AllowedOrigin_Test@5bbeffcd]" name="negativePost_Test" duration-ms="1370" started-at="2013-10-28T19:20:19Z" finished-at="2013-10-28T19:20:21Z">
          <exception class="java.lang.AssertionError">
            <message>
              <![CDATA[expected [200] but found [Failure]]]>
            </message>
            <full-stacktrace>
              <![CDATA[java.lang.AssertionError: expected [200] but found [Failure]
	at org.testng.Assert.fail(Assert.java:94)
	at org.testng.Assert.failNotEquals(Assert.java:494)
	at org.testng.Assert.assertEquals(Assert.java:123)
	at org.testng.Assert.assertEquals(Assert.java:176)
	at org.testng.Assert.assertEquals(Assert.java:186)
	at test.java.Cors_Positive_AllowedOrigin_Test.negativePost_Test(Cors_Positive_AllowedOrigin_Test.java:48)
	at sun.reflect.NativeMethodAccessorImpl.invoke0(Native Method)
	at sun.reflect.NativeMethodAccessorImpl.invoke(Unknown Source)
	at sun.reflect.DelegatingMethodAccessorImpl.invoke(Unknown Source)
	at java.lang.reflect.Method.invoke(Unknown Source)
	at org.testng.internal.MethodInvocationHelper.invokeMethod(MethodInvocationHelper.java:84)
	at org.testng.internal.Invoker.invokeMethod(Invoker.java:714)
	at org.testng.internal.Invoker.invokeTestMethod(Invoker.java:901)
	at org.testng.internal.Invoker.invokeTestMethods(Invoker.java:1231)
	at org.testng.internal.TestMethodWorker.invokeTestMethods(TestMethodWorker.java:127)
	at org.testng.internal.TestMethodWorker.run(TestMethodWorker.java:111)
	at org.testng.TestRunner.privateRun(TestRunner.java:767)
	at org.testng.TestRunner.run(TestRunner.java:617)
	at org.testng.SuiteRunner.runTest(SuiteRunner.java:334)
	at org.testng.SuiteRunner.runSequentially(SuiteRunner.java:329)
	at org.testng.SuiteRunner.privateRun(SuiteRunner.java:291)
	at org.testng.SuiteRunner.run(SuiteRunner.java:240)
	at org.testng.SuiteRunnerWorker.runSuite(SuiteRunnerWorker.java:52)
	at org.testng.SuiteRunnerWorker.run(SuiteRunnerWorker.java:86)
	at org.testng.TestNG.runSuitesSequentially(TestNG.java:1224)
	at org.testng.TestNG.runSuitesLocally(TestNG.java:1149)
	at org.testng.TestNG.run(TestNG.java:1057)
	at org.testng.remote.RemoteTestNG.run(RemoteTestNG.java:111)
	at org.testng.remote.RemoteTestNG.initAndRun(RemoteTestNG.java:204)
	at org.testng.remote.RemoteTestNG.main(RemoteTestNG.java:175)
]]>
            </full-stacktrace>
          </exception> <!-- java.lang.AssertionError -->
          <reporter-output>
          </reporter-output>
        </test-method> <!-- negativePost_Test -->
        <test-method status="FAIL" signature="negativePut_Test()[pri:0, instance:test.java.Cors_Positive_AllowedOrigin_Test@5bbeffcd]" name="negativePut_Test" duration-ms="1702" started-at="2013-10-28T19:20:21Z" finished-at="2013-10-28T19:20:22Z">
          <exception class="java.lang.AssertionError">
            <message>
              <![CDATA[expected [200] but found [Failure]]]>
            </message>
            <full-stacktrace>
              <![CDATA[java.lang.AssertionError: expected [200] but found [Failure]
	at org.testng.Assert.fail(Assert.java:94)
	at org.testng.Assert.failNotEquals(Assert.java:494)
	at org.testng.Assert.assertEquals(Assert.java:123)
	at org.testng.Assert.assertEquals(Assert.java:176)
	at org.testng.Assert.assertEquals(Assert.java:186)
	at test.java.Cors_Positive_AllowedOrigin_Test.negativePut_Test(Cors_Positive_AllowedOrigin_Test.java:54)
	at sun.reflect.NativeMethodAccessorImpl.invoke0(Native Method)
	at sun.reflect.NativeMethodAccessorImpl.invoke(Unknown Source)
	at sun.reflect.DelegatingMethodAccessorImpl.invoke(Unknown Source)
	at java.lang.reflect.Method.invoke(Unknown Source)
	at org.testng.internal.MethodInvocationHelper.invokeMethod(MethodInvocationHelper.java:84)
	at org.testng.internal.Invoker.invokeMethod(Invoker.java:714)
	at org.testng.internal.Invoker.invokeTestMethod(Invoker.java:901)
	at org.testng.internal.Invoker.invokeTestMethods(Invoker.java:1231)
	at org.testng.internal.TestMethodWorker.invokeTestMethods(TestMethodWorker.java:127)
	at org.testng.internal.TestMethodWorker.run(TestMethodWorker.java:111)
	at org.testng.TestRunner.privateRun(TestRunner.java:767)
	at org.testng.TestRunner.run(TestRunner.java:617)
	at org.testng.SuiteRunner.runTest(SuiteRunner.java:334)
	at org.testng.SuiteRunner.runSequentially(SuiteRunner.java:329)
	at org.testng.SuiteRunner.privateRun(SuiteRunner.java:291)
	at org.testng.SuiteRunner.run(SuiteRunner.java:240)
	at org.testng.SuiteRunnerWorker.runSuite(SuiteRunnerWorker.java:52)
	at org.testng.SuiteRunnerWorker.run(SuiteRunnerWorker.java:86)
	at org.testng.TestNG.runSuitesSequentially(TestNG.java:1224)
	at org.testng.TestNG.runSuitesLocally(TestNG.java:1149)
	at org.testng.TestNG.run(TestNG.java:1057)
	at org.testng.remote.RemoteTestNG.run(RemoteTestNG.java:111)
	at org.testng.remote.RemoteTestNG.initAndRun(RemoteTestNG.java:204)
	at org.testng.remote.RemoteTestNG.main(RemoteTestNG.java:175)
]]>
            </full-stacktrace>
          </exception> <!-- java.lang.AssertionError -->
          <reporter-output>
          </reporter-output>
        </test-method> <!-- negativePut_Test -->
        <test-method status="PASS" signature="tear()[pri:0, instance:test.java.Cors_Positive_AllowedOrigin_Test@5bbeffcd]" name="tear" is-config="true" duration-ms="182" started-at="2013-10-28T19:20:22Z" finished-at="2013-10-28T19:20:22Z">
          <reporter-output>
          </reporter-output>
        </test-method> <!-- tear -->
      </class> <!-- test.java.Cors_Positive_AllowedOrigin_Test -->
    </test> <!-- Default test -->
  </suite> <!-- Default suite -->
</testng-results>
